thread 'main' panicked at 'called `Result::unwrap()` on an `Err` value: InternalError { message: "[/Users/oyelowo/.cargo/registry/src/github.com-1ecc6299db9ec823/tikv-client-pd-0.1.0/src/cluster.rs:264]: failed to connect to [Member { name: \"basic-pd-0\", member_id: 7441053368211532809, peer_urls: [\"http://basic-pd-0.basic-pd-peer.tidb-cluster.svc:2380\"], client_urls: [\"http://basic-pd-0.basic-pd-peer.tidb-cluster.svc:2379\"], leader_priority: 0, deploy_path: \"\", binary_version: \"\", git_hash: \"\", dc_location: \"\" }]" }', src/main.rs:66:63
note: run with `RUST_BACKTRACE=1` environment variable to display a backtrace